Workbook

Sheet 컬럼_old
A1: 사업범위 여부 | B1: 주제영역 | C1: schema | D1: 테이블 영문명 | E1: 컬럼 영문명 | F1: 컬럼 한글명 | G1: 컬럼 설명 | H1: 연관 엔터티명 | J1: 자료 타입 | K1: 자료 길이 | L1: 자료소수점길이 | M1: 자료 형식 | N1: NOT NULL 여부 | O1: PK정보 | P1: FK정보 | Q1: 인덱스명 | R1: 인덱스 순번 | S1: AK정보 | T1: 제약조건 | U1: 개인정보여부 | V1: 암호화 여부 | W1: 공개/비공개여부
A2: N | B2: 통계 | C2: bksp | D2: TBL_VSTR_STTUS_INFO | E2: VSTR_CNT_STTUS_YM | F2: 방문자_수_현황_연월 | G2: 방문자_수_현황_연월 | H2: 방문자_현황_정보 | I2: =VLOOKUP(F2,표준용어사전!$B:$D,3,FALSE) -> 연월C6 | J2: CHAR | K2: 6 | L2: - | M2: 6자리 문자 | N2: Y | O2: PK01 | T2: YYYY : 0001~9999, MM : 01~12 | U2: N | V2: N
A3: N | B3: 통계 | C3: bksp | D3: TBL_VSTR_STTUS_INFO | E3: VSTR_LGT_CNT | F3: 방문자_로그아웃_수 | G3: 방문자_로그아웃_수 | H3: 방문자_현황_정보 | I3: =VLOOKUP(F3,표준용어사전!$B:$D,3,FALSE) -> 수N10 | J3: NUMERIC | K3: 10 | L3: - | M3: 9999999999 | N3: N | U3: N | V3: N
A4: N | B4: 통계 | C4: bksp | D4: TBL_VSTR_STTUS_INFO | E4: VSTR_LGN_CNT | F4: 방문자_로그인_수 | G4: 방문자_로그인_수 | H4: 방문자_현황_정보 | I4: =VLOOKUP(F4,표준용어사전!$B:$D,3,FALSE) -> 수N10 | J4: NUMERIC | K4: 10 | L4: - | M4: 9999999999 | N4: N | U4: N | V4: N
A5: N | B5: 통계 | C5: bksp | D5: TBL_VSTR_STTUS_INFO | E5: VSTR_EXPERT_CNT | F5: 방문자_전문가_수 | G5: 방문자_전문가_수 | H5: 방문자_현황_정보 | I5: =VLOOKUP(F5,표준용어사전!$B:$D,3,FALSE) -> 수N10 | J5: NUMERIC | K5: 10 | L5: - | M5: 9999999999 | N5: N | U5: N | V5: N
A6: N | B6: 통계 | C6: bksp | D6: TBL_VSTR_STTUS_INFO | E6: VSTR_LGT_STAY_HR | F6: 방문자_로그아웃_체류_시간 | G6: 방문자_로그아웃_체류_시간 | H6: 방문자_현황_정보 | I6: =VLOOKUP(F6,표준용어사전!$B:$D,3,FALSE) -> 시분초N10 | J6: NUMERIC | K6: 10 | L6: - | M6: 9999999999 | N6: N | U6: N | V6: N
A7: N | B7: 통계 | C7: bksp | D7: TBL_VSTR_STTUS_INFO | E7: VSTR_LGN_STAY_HR | F7: 방문자_로그인_체류_시간 | G7: 방문자_로그인_체류_시간 | H7: 방문자_현황_정보 | I7: =VLOOKUP(F7,표준용어사전!$B:$D,3,FALSE) -> 시분초N10 | J7: NUMERIC | K7: 10 | L7: - | M7: 9999999999 | N7: N | U7: N | V7: N
A8: N | B8: 통계 | C8: bksp | D8: TBL_VSTR_STTUS_INFO | E8: VSTR_EXPERT_STAY_HR | F8: 방문자_전문가_체류_시간 | G8: 방문자_전문가_체류_시간 | H8: 방문자_현황_정보 | I8: =VLOOKUP(F8,표준용어사전!$B:$D,3,FALSE) -> 시분초N10 | J8: NUMERIC | K8: 10 | L8: - | M8: 9999999999 | N8: N | U8: N | V8: N
A9: Y | B9: 통계 | C9: bksp | D9: TBL_VSTR_STTUS_INFO | E9: CLSF_SYSTM_STAY_HR | F9: 분류_체계_체류_시간 | G9: 분류_체계_체류_시간 | H9: 방문자_현황_정보 | I9: =VLOOKUP(F9,표준용어사전!$B:$D,3,FALSE) -> 시분초N10 | J9: NUMERIC | K9: 10 | L9: - | M9: 9999999999 | N9: N | U9: N | V9: N
A10: N | B10: 생태모방사례 | C10: bksp | D10: TBL_SKLL_TCHNLGY_CNTNTS_MAPNG | E10: CNTNTS_NO | F10: 컨텐츠_번호 | G10: 컨텐츠_번호 | H10: 기능_기술_컨텐츠_매핑 | I10: =VLOOKUP(F10,표준용어사전!$B:$D,3,FALSE) -> #N/A | J10: NUMERIC | K10: 10 | L10: - | M10: 9999999999 | N10: Y | O10: PK01 | U10: N | V10: N
A11: N | B11: 생태모방사례 | C11: bksp | D11: TBL_SKLL_TCHNLGY_CNTNTS_MAPNG | E11: TCHNLGY_CD | F11: 기술_코드 | G11: 기술_코드 | H11: 기능_기술_컨텐츠_매핑 | I11: =VLOOKUP(F11,표준용어사전!$B:$D,3,FALSE) -> 코드V50 | J11: CHAR | K11: 50 | L11: - | M11: 50자리 문자 | N11: Y | O11: PK02 | U11: N | V11: N
A12: N | B12: 생태모방사례 | C12: bksp | D12: TBL_SKLL_TCHNLGY_CNTNTS_MAPNG | E12: REG_DT | F12: 등록_일시 | G12: 등록_일시 | H12: 기능_기술_컨텐츠_매핑 | I12: =VLOOKUP(F12,표준용어사전!$B:$D,3,FALSE) -> 연월일시분초TS | J12: TIMESTAMP | K12: - | L12: - | M12: YYYYMMDDHH24MISS | N12: Y | T12: YYYY : 0001~9999, MM : 01~12, DD : 01~31, HH : 00~23, MI : 00~59, SS : 00~59 | U12: N | V12: N
A13: N | B13: 생태모방사례 | C13: bksp | D13: TBL_SKLL_TCHNLGY_CNTNTS_MAPNG | E13: REG_ID | F13: 등록_아이디 | G13: 등록_아이디 | H13: 기능_기술_컨텐츠_매핑 | I13: =VLOOKUP(F13,표준용어사전!$B:$D,3,FALSE) -> 명V20 | J13: VARCHAR | K13: 20 | L13: - | M13: 20자리 이내 문자 | N13: N | U13: N | V13: N
A14: N | B14: 생태모방사례 | C14: bksp | D14: TBL_SKLL_TCHNLGY_CNTNTS_MAPNG | E14: MDFCN_DT | F14: 수정_일시 | G14: 수정_일시 | H14: 기능_기술_컨텐츠_매핑 | I14: =VLOOKUP(F14,표준용어사전!$B:$D,3,FALSE) -> 연월일시분초TS | J14: TIMESTAMP | K14: - | L14: - | M14: YYYYMMDDHH24MISS | N14: N | T14: YYYY : 0001~9999, MM : 01~12, DD : 01~31, HH : 00~23, MI : 00~59, SS : 00~59 | U14: N | V14: N
A15: N | B15: 생태모방사례 | C15: bksp | D15: TBL_SKLL_TCHNLGY_CNTNTS_MAPNG | E15: MDFCN_ID | F15: 수정_아이디 | G15: 수정_아이디 | H15: 기능_기술_컨텐츠_매핑 | I15: =VLOOKUP(F15,표준용어사전!$B:$D,3,FALSE) -> 명V20 | J15: VARCHAR | K15: 20 | L15: - | M15: 20자리 이내 문자 | N15: N | U15: N | V15: N
A16: N | B16: 생태모방사례 | C16: bksp | D16: TBL_SKLL_SECT_CNTNTS_MAPNG | E16: CNTNTS_NO | F16: 컨텐츠_번호 | G16: 컨텐츠_번호 | H16: 기능_부문_컨텐츠_매핑 | I16: =VLOOKUP(F16,표준용어사전!$B:$D,3,FALSE) -> #N/A | J16: NUMERIC | K16: 10 | L16: - | M16: 9999999999 | N16: Y | O16: PK01 | U16: N | V16: N
A17: N | B17: 생태모방사례 | C17: bksp | D17: TBL_SKLL_SECT_CNTNTS_MAPNG | E17: SECT_CD | F17: 부문_코드 | G17: 부문_코드 | H17: 기능_부문_컨텐츠_매핑 | I17: =VLOOKUP(F17,표준용어사전!$B:$D,3,FALSE) -> 코드V50 | J17: CHAR | K17: 50 | L17: - | M17: 50자리 문자 | N17: Y | O17: PK02 | U17: N | V17: N
A18: N | B18: 생태모방사례 | C18: bksp | D18: TBL_SKLL_SECT_CNTNTS_MAPNG | E18: REG_DT | F18: 등록_일시 | G18: 등록_일시 | H18: 기능_부문_컨텐츠_매핑 | I18: =VLOOKUP(F18,표준용어사전!$B:$D,3,FALSE) -> 연월일시분초TS | J18: TIMESTAMP | K18: - | L18: - | M18: YYYYMMDDHH24MISS | N18: Y | T18: YYYY : 0001~9999, MM : 01~12, DD : 01~31, HH : 00~23, MI : 00~59, SS : 00~59 | U18: N | V18: N
A19: N | B19: 생태모방사례 | C19: bksp | D19: TBL_SKLL_SECT_CNTNTS_MAPNG | E19: REG_ID | F19: 등록_아이디 | G19: 등록_아이디 | H19: 기능_부문_컨텐츠_매핑 | I19: =VLOOKUP(F19,표준용어사전!$B:$D,3,FALSE) -> 명V20 | J19: VARCHAR | K19: 20 | L19: - | M19: 20자리 이내 문자 | N19: N | U19: N | V19: N
A20: N | B20: 생태모방사례 | C20: bksp | D20: TBL_SKLL_SECT_CNTNTS_MAPNG | E20: MDFCN_DT | F20: 수정_일시 | G20: 수정_일시 | H20: 기능_부문_컨텐츠_매핑 | I20: =VLOOKUP(F20,표준용어사전!$B:$D,3,FALSE) -> 연월일시분초TS | J20: TIMESTAMP | K20: - | L20: - | M20: YYYYMMDDHH24MISS | N20: N | T20: YYYY : 0001~9999, MM : 01~12, DD : 01~31, HH : 00~23, MI : 00~59, SS : 00~59 | U20: N | V20: N
A21: N | B21: 생태모방사례 | C21: bksp | D21: TBL_SKLL_SECT_CNTNTS_MAPNG | E21: MDFCN_ID | F21: 수정_아이디 | G21: 수정_아이디 | H21: 기능_부문_컨텐츠_매핑 | I21: =VLOOKUP(F21,표준용어사전!$B:$D,3,FALSE) -> 명V20 | J21: VARCHAR | K21: 20 | L21: - | M21: 20자리 이내 문자 | N21: N | U21: N | V21: N
A22: N | B22: 생태모방사례 | C22: bksp | D22: TBL_SKLL_ETC_CD_MNG | E22: ETC_CD_SE | F22: 기타_코드_구분 | G22: 기타_코드_구분 | H22: 기능_기타_코드_관리 | I22: =VLOOKUP(F22,표준용어사전!$B:$D,3,FALSE) -> #N/A | J22: VARCHAR | K22: 2000 | L22: - | M22: 2000자리 이내 문자 | N22: Y | O22: PK01 | U22: N | V22: N
A23: N | B23: 생태모방사례 | C23: bksp | D23: TBL_SKLL_ETC_CD_MNG | E23: ETC_CD | F23: 기타_코드 | G23: 기타_코드 | H23: 기능_기타_코드_관리 | I23: =VLOOKUP(F23,표준용어사전!$B:$D,3,FALSE) -> 코드V50 | J23: CHAR | K23: 50 | L23: - | M23: 50자리 문자 | N23: Y | O23: PK02 | U23: N | V23: N
A24: N | B24: 생태모방사례 | C24: bksp | D24: TBL_SKLL_ETC_CD_MNG | E24: ENG_CD_DC | F24: 영문_코드_서술 | G24: 영문_코드_설명 | H24: 기능_기타_코드_관리 | I24: =VLOOKUP(F24,표준용어사전!$B:$D,3,FALSE) -> #N/A | J24: VARCHAR | K24: 2000 | L24: - | M24: 2000자리 이내 문자 | N24: N | U24: N | V24: N
A25: N | B25: 생태모방사례 | C25: bksp | D25: TBL_SKLL_ETC_CD_MNG | E25: KORN_CD_DC | F25: 한글_코드_서술 | G25: 한글_코드_설명 | H25: 기능_기타_코드_관리 | I25: =VLOOKUP(F25,표준용어사전!$B:$D,3,FALSE) -> #N/A | J25: VARCHAR | K25: 2000 | L25: - | M25: 2000자리 이내 문자 | N25: N | U25: N | V25: N
A26: N | B26: 생태모방사례 | C26: bksp | D26: TBL_SKLL_ETC_CD_MNG | E26: REG_DT | F26: 등록_일시 | G26: 등록_일시 | H26: 기능_기타_코드_관리 | I26: =VLOOKUP(F26,표준용어사전!$B:$D,3,FALSE) -> 연월일시분초TS | J26: TIMESTAMP | K26: - | L26: - | M26: YYYYMMDDHH24MISS | N26: Y | T26: YYYY : 0001~9999, MM : 01~12, DD : 01~31, HH : 00~23, MI : 00~59, SS : 00~59 | U26: N | V26: N
A27: N | B27: 생태모방사례 | C27: bksp | D27: TBL_SKLL_ETC_CD_MNG | E27: REG_ID | F27: 등록_아이디 | G27: 등록_아이디 | H27: 기능_기타_코드_관리 | I27: =VLOOKUP(F27,표준용어사전!$B:$D,3,FALSE) -> 명V20 | J27: VARCHAR | K27: 20 | L27: - | M27: 20자리 이내 문자 | N27: N | U27: N | V27: N
A28: N | B28: 생태모방사례 | C28: bksp | D28: TBL_SKLL_ETC_CD_MNG | E28: MDFCN_DT | F28: 수정_일시 | G28: 수정_일시 | H28: 기능_기타_코드_관리 | I28: =VLOOKUP(F28,표준용어사전!$B:$D,3,FALSE) -> 연월일시분초TS | J28: TIMESTAMP | K28: - | L28: - | M28: YYYYMMDDHH24MISS | N28: N | T28: YYYY : 0001~9999, MM : 01~12, DD : 01~31, HH : 00~23, MI : 00~59, SS : 00~59 | U28: N | V28: N
A29: N | B29: 생태모방사례 | C29: bksp | D29: TBL_SKLL_ETC_CD_MNG | E29: MDFCN_ID | F29: 수정_아이디 | G29: 수정_아이디 | H29: 기능_기타_코드_관리 | I29: =VLOOKUP(F29,표준용어사전!$B:$D,3,FALSE) -> 명V20 | J29: VARCHAR | K29: 20 | L29: - | M29: 20자리 이내 문자 | N29: N | U29: N | V29: N
A30: N | B30: 생태모방사례 | C30: bksp | D30: TBL_SKLL_CNTNTS_REL | E30: CNTNTS_NO | F30: 컨텐츠_번호 | G30: 컨텐츠_번호 | H30: 기능_컨텐츠_관계 | I30: =VLOOKUP(F30,표준용어사전!$B:$D,3,FALSE) -> #N/A | J30: NUMERIC | K30: 10 | L30: - | M30: 9999999999 | N30: Y | O30: PK01 | U30: N | V30: N
A31: N | B31: 생태모방사례 | C31: bksp | D31: TBL_SKLL_CNTNTS_REL | E31: CNTNTS_REL_NO | F31: 컨텐츠_관계_번호 | G31: 컨텐츠_관계_번호 | H31: 기능_컨텐츠_관계 | I31: =VLOOKUP(F31,표준용어사전!$B:$D,3,FALSE) -> #N/A | J31: NUMERIC | K31: 10 | L31: - | M31: 9999999999 | N31: Y | O31: PK02 | U31: N | V31: N
A32: N | B32: 생태모방사례 | C32: bksp | D32: TBL_SKLL_CNTNTS_REL | E32: CNTNTS_SE_NM | F32: 컨텐츠_구분_명 | G32: 컨텐츠_구분_명 | H32: 기능_컨텐츠_관계 | I32: =VLOOKUP(F32,표준용어사전!$B:$D,3,FALSE) -> #N/A | J32: VARCHAR | K32: 100 | L32: - | M32: 100자리 이내 문자 | N32: N | U32: N | V32: N
A33: N | B33: 생태모방사례 | C33: bksp | D33: TBL_SKLL_CNTNTS_REL | E33: REG_DT | F33: 등록_일시 | G33: 등록_일시 | H33: 기능_컨텐츠_관계 | I33: =VLOOKUP(F33,표준용어사전!$B:$D,3,FALSE) -> 연월일시분초TS | J33: TIMESTAMP | K33: - | L33: - | M33: YYYYMMDDHH24MISS | N33: Y | T33: YYYY : 0001~9999, MM : 01~12, DD : 01~31, HH : 00~23, MI : 00~59, SS : 00~59 | U33: N | V33: N
A34: N | B34: 생태모방사례 | C34: bksp | D34: TBL_SKLL_CNTNTS_REL | E34: REG_ID | F34: 등록_아이디 | G34: 등록_아이디 | H34: 기능_컨텐츠_관계 | I34: =VLOOKUP(F34,표준용어사전!$B:$D,3,FALSE) -> 명V20 | J34: VARCHAR | K34: 20 | L34: - | M34: 20자리 이내 문자 | N34: N | U34: N | V34: N
A35: N | B35: 생태모방사례 | C35: bksp | D35: TBL_SKLL_CNTNTS_REL | E35: MDFCN_DT | F35: 수정_일시 | G35: 수정_일시 | H35: 기능_컨텐츠_관계 | I35: =VLOOKUP(F35,표준용어사전!$B:$D,3,FALSE) -> 연월일시분초TS | J35: TIMESTAMP | K35: - | L35: - | M35: YYYYMMDDHH24MISS | N35: N | T35: YYYY : 0001~9999, MM : 01~12, DD : 01~31, HH : 00~23, MI : 00~59, SS : 00~59 | U35: N | V35: N
A36: N | B36: 생태모방사례 | C36: bksp | D36: TBL_SKLL_CNTNTS_REL | E36: MDFCN_ID | F36: 수정_아이디 | G36: 수정_아이디 | H36: 기능_컨텐츠_관계 | I36: =VLOOKUP(F36,표준용어사전!$B:$D,3,FALSE) -> 명V20 | J36: VARCHAR | K36: 20 | L36: - | M36: 20자리 이내 문자 | N36: N | U36: N | V36: N
A37: N | B37: 생태모방사례 | C37: bksp | D37: TBL_SKLL_CNTNTS_MSTR | E37: CNTNTS_NO | F37: 컨텐츠_번호 | G37: 컨텐츠_번호 | H37: 기능_컨텐츠_마스터 | I37: =VLOOKUP(F37,표준용어사전!$B:$D,3,FALSE) -> #N/A | J37: NUMERIC | K37: 10 | L37: - | M37: 9999999999 | N37: Y | O37: PK01 | U37: N | V37: N
A38: N | B38: 생태모방사례 | C38: bksp | D38: TBL_SKLL_CNTNTS_MSTR | E38: CNTNTS_SE_NM | F38: 컨텐츠_구분_명 | G38: 컨텐츠_구분_명 | H38: 기능_컨텐츠_마스터 | I38: =VLOOKUP(F38,표준용어사전!$B:$D,3,FALSE) -> #N/A | J38: VARCHAR | K38: 100 | L38: - | M38: 100자리 이내 문자 | N38: N | U38: N | V38: N
A39: N | B39: 생태모방사례 | C39: bksp | D39: TBL_SKLL_CNTNTS_MSTR | E39: CNTNTS_TTL | F39: 컨텐츠_제목 | G39: 컨텐츠_제목 | H39: 기능_컨텐츠_마스터 | I39: =VLOOKUP(F39,표준용어사전!$B:$D,3,FALSE) -> #N/A | J39: VARCHAR | K39: 512 | L39: - | M39: 512자리 이내 문자 | N39: N | U39: N | V39: N
A40: N | B40: 생태모방사례 | C40: bksp | D40: TBL_SKLL_CNTNTS_MSTR | E40: CNTNTS_SBTTL | F40: 컨텐츠_부제목 | G40: 컨텐츠_부제목 | H40: 기능_컨텐츠_마스터 | I40: =VLOOKUP(F40,표준용어사전!$B:$D,3,FALSE) -> #N/A | J40: VARCHAR | K40: 256 | L40: - | M40: 256자리 이내 문자 | N40: N | U40: N | V40: N
...

Sheet 컬럼
A1: 사업범위 여부 | B1: 주제영역 | C1: schema | D1: 테이블 영문명 | E1: 컬럼 영문명 | F1: 컬럼 한글명 | G1: 컬럼 설명 | H1: 연관 엔터티명 | I1: 도메인명 | J1: 자료 타입 | K1: 자료 길이 | L1: 자료소수점길이 | M1: 자료 형식 | N1: NOT NULL 여부 | O1: PK정보 | P1: FK정보 | Q1: 인덱스명 | R1: 인덱스 순번 | S1: AK정보 | T1: 제약조건 | U1: 개인정보여부 | V1: 암호화 여부 | W1: 공개/비공개여부
A2: N | B2: 생물종 | C2: bksp | D2: TBL_BIOSPC_BSC | E2: EOL_ID | F2: EOL_아이디 | G2: EOL_아이디 | H2: 생물종_기본 | I2: =VLOOKUP(E2,표준용어사전!$C$2:$D$494, 2, FALSE) -> 명V20 | J2: VARCHAR | K2: 20 | L2: - | M2: 20자리 이내 문자 | N2: Y | O2: PK01 | U2: N | V2: N
A3: N | B3: 생물종 | C3: bksp | D3: TBL_BIOSPC_BSC | E3: EOL_CLSF_ID | F3: EOL_분류_아이디 | G3: EOL_분류_아이디 | H3: 생물종_기본 | I3: =VLOOKUP(E3,표준용어사전!$C$2:$D$494, 2, FALSE) -> 명V50 | J3: VARCHAR | K3: 50 | L3: - | M3: 50자리 이내 문자 | N3: N | U3: N | V3: N
A4: N | B4: 생물종 | C4: bksp | D4: TBL_BIOSPC_BSC | E4: EOL_UP_CLSF_ID | F4: EOL_상위_분류_아이디 | G4: EOL_상위_분류_아이디 | H4: 생물종_기본 | I4: =VLOOKUP(E4,표준용어사전!$C$2:$D$494, 2, FALSE) -> 명V50 | J4: VARCHAR | K4: 50 | L4: - | M4: 50자리 이내 문자 | N4: N | U4: N | V4: N
A5: N | B5: 생물종 | C5: bksp | D5: TBL_BIOSPC_BSC | E5: GBIF_MPNG_YN | F5: GBIF_매핑_여부 | G5: GBIF_매핑_여부 | H5: 생물종_기본 | I5: =VLOOKUP(E5,표준용어사전!$C$2:$D$494, 2, FALSE) -> 여부C1 | J5: CHAR | K5: 1 | L5: - | M5: 1자리 문자 | N5: N | U5: N | V5: N
A6: N | B6: 생물종 | C6: bksp | D6: TBL_BIOSPC_BSC | E6: GBIF_CLSF_ID | F6: GBIF_분류_아이디 | G6: GBIF_분류_아이디 | H6: 생물종_기본 | I6: =VLOOKUP(E6,표준용어사전!$C$2:$D$494, 2, FALSE) -> 명V50 | J6: VARCHAR | K6: 50 | L6: - | M6: 50자리 이내 문자 | N6: N | U6: N | V6: N
A7: N | B7: 생물종 | C7: bksp | D7: TBL_BIOSPC_BSC | E7: GBIF_SPCS_ID | F7: GBIF_종_아이디 | G7: GBIF_종_아이디 | H7: 생물종_기본 | I7: =VLOOKUP(E7,표준용어사전!$C$2:$D$494, 2, FALSE) -> 명V50 | J7: VARCHAR | K7: 50 | L7: - | M7: 50자리 이내 문자 | N7: N | U7: N | V7: N
A8: N | B8: 생물종 | C8: bksp | D8: TBL_BIOSPC_BSC | E8: GBIF_CLSF_GRD_NM | F8: GBIF_분류_등급_명 | G8: GBIF_분류_등급_명 | H8: 생물종_기본 | I8: =VLOOKUP(E8,표준용어사전!$C$2:$D$494, 2, FALSE) -> 명V80 | J8: VARCHAR | K8: 80 | L8: - | M8: 80자리 이내 문자 | N8: N | U8: N | V8: N
A9: N | B9: 생물종 | C9: bksp | D9: TBL_BIOSPC_BSC | E9: EOL_SPCS_TXNM_NM | F9: EOL_종_분류학_명 | G9: EOL_종_분류학_명 | H9: 생물종_기본 | I9: =VLOOKUP(E9,표준용어사전!$C$2:$D$494, 2, FALSE) -> 명V256 | J9: VARCHAR | K9: 256 | L9: - | M9: 256자리 이내 문자 | N9: N | U9: N | V9: N
A10: N | B10: 생물종 | C10: bksp | D10: TBL_BIOSPC_BSC | E10: EOL_SPCS_FRMLY_NM | F10: EOL_종_정식_명 | G10: EOL_종_정식_명 | H10: 생물종_기본 | I10: =VLOOKUP(E10,표준용어사전!$C$2:$D$494, 2, FALSE) -> 명V256 | J10: VARCHAR | K10: 256 | L10: - | M10: 256자리 이내 문자 | N10: N | U10: N | V10: N
A11: N | B11: 생물종 | C11: bksp | D11: TBL_BIOSPC_BSC | E11: DMST_SPCS_EXST_YN | F11: 국내_종_존재_여부 | G11: 국내_종_존재_여부 | H11: 생물종_기본 | I11: =VLOOKUP(E11,표준용어사전!$C$2:$D$494, 2, FALSE) -> 여부C1 | J11: CHAR | K11: 1 | L11: - | M11: 1자리 문자 | N11: N | U11: N | V11: N
A12: N | B12: 생물종 | C12: bksp | D12: TBL_BIOSPC_BSC | E12: ADW_EXST_YN | F12: 동물다양성웹_존재_여부 | G12: 동물다양성웹_존재_여부 | H12: 생물종_기본 | I12: =VLOOKUP(E12,표준용어사전!$C$2:$D$494, 2, FALSE) -> 여부C1 | J12: CHAR | K12: 1 | L12: - | M12: 1자리 문자 | N12: N | U12: N | V12: N
A13: N | B13: 생물종 | C13: bksp | D13: TBL_BIOSPC_BSC | E13: KDM_TXNM_SNTFNM | F13: 계_분류학_학명 | G13: 계_분류학_학명 | H13: 생물종_기본 | I13: =VLOOKUP(E13,표준용어사전!$C$2:$D$494, 2, FALSE) -> 학명V256 | J13: VARCHAR | K13: 256 | L13: - | M13: 256자리 이내 문자 | N13: N | U13: N | V13: N
A14: N | B14: 생물종 | C14: bksp | D14: TBL_BIOSPC_BSC | E14: KDM_TXNM_LCNM | F14: 계_분류학_국명 | G14: 계_분류학_국명 | H14: 생물종_기본 | I14: =VLOOKUP(E14,표준용어사전!$C$2:$D$494, 2, FALSE) -> 국명V256 | J14: VARCHAR | K14: 256 | L14: - | M14: 256자리 이내 문자 | N14: N | U14: N | V14: N
... A32: N | B32: 생물종 | C32: bksp | D32: TBL_BIOSPC_BSC | E32: SPCS_TXNM_LCNM | F32: 종_분류학_국명 | G32: 종_분류학_국명 | H32: 생물종_기본 | I32: =VLOOKUP(E32,표준용어사전!$C$2:$D$494, 2, FALSE) -> 국명V256 | J32: VARCHAR | K32: 256 | L32: - | M32: 256자리 이내 문자 | N32: N | U32: N | V32: N
A33: N | B33: 생물종 | C33: bksp | D33: TBL_BIOSPC_BSC | E33: EOL_CLSF_LYR_CN | F33: EOL_분류_계층_내용 | G33: EOL_분류_계층_내용 | H33: 생물종_기본 | I33: =VLOOKUP(E33,표준용어사전!$C$2:$D$494, 2, FALSE) -> 내용TXT | J33: TEXT | K33: - | L33: - | M33: 문자 | N33: N | U33: N | V33: N
A34: N | B34: 생물종 | C34: bksp | D34: TBL_BIOSPC_BSC | E34: EOL_LVB_NM_INDX_CMPTN_YN | F34: EOL_생물_명_색인_완료_여부 | G34: EOL_생물_명_색인_완료_여부 | H34: 생물종_기본 | I34: =VLOOKUP(E34,표준용어사전!$C$2:$D$494, 2, FALSE) -> 여부C1 | J34: CHAR | K34: 1 | L34: - | M34: 1자리 문자 | N34: N | U34: N | V34: N
A35: N | B35: 생물종 | C35: bksp | D35: TBL_BIOSPC_BSC | E35: REG_DT | F35: 등록_일시 | G35: 등록_일시 | H35: 생물종_기본 | I35: =VLOOKUP(E35,표준용어사전!$C$2:$D$494, 2, FALSE) -> 연월일시분초TS | J35: TIMESTAMP | K35: - | L35: - | M35: YYYYMMDDHH24MISS | N35: Y | U35: N | V35: N
A36: N | B36: 생물종 | C36: bksp | D36: TBL_BIOSPC_BSC | E36: REG_ID | F36: 등록_아이디 | G36: 등록_아이디 | H36: 생물종_기본 | I36: =VLOOKUP(E36,표준용어사전!$C$2:$D$494, 2, FALSE) -> 명V20 | J36: VARCHAR | K36: 20 | L36: - | M36: 20자리 이내 문자 | N36: N | U36: N | V36: N
A37: N | B37: 생물종 | C37: bksp | D37: TBL_BIOSPC_BSC | E37: MDFCN_DT | F37: 수정_일시 | G37: 수정_일시 | H37: 생물종_기본 | I37: =VLOOKUP(E37,표준용어사전!$C$2:$D$494, 2, FALSE) -> 연월일시분초TS | J37: TIMESTAMP | K37: - | L37: - | M37: YYYYMMDDHH24MISS | N37: N | U37: N | V37: N
A38: N | B38: 생물종 | C38: bksp | D38: TBL_BIOSPC_BSC | E38: MDFCN_ID | F38: 수정_아이디 | G38: 수정_아이디 | H38: 생물종_기본 | I38: =VLOOKUP(E38,표준용어사전!$C$2:$D$494, 2, FALSE) -> 명V20 | J38: VARCHAR | K38: 20 | L38: - | M38: 20자리 이내 문자 | N38: N | U38: N | V38: N
A39: N | B39: 생물종 | C39: bksp | D39: TBL_BIOSPC_RGN_LANG | E39: RGN_LANG_NO | F39: 지역_언어_번호 | G39: 지역_언어_번호 | H39: 생물종_지역_언어 | I39: =VLOOKUP(E39,표준용어사전!$C$2:$D$494, 2, FALSE) -> 번호I | J39: INT4 | K39: - | L39: - | M39: 0 이상의 정수 | N39: Y | O39: PK01 | U39: N | V39: N
A40: N | B40: 생물종 | C40: bksp | D40: TBL_BIOSPC_RGN_LANG | E40: EOL_ID | F40: EOL_아이디 | G40: EOL_아이디 | H40: 생물종_지역_언어 | I40: =VLOOKUP(E40,표준용어사전!$C$2:$D$494, 2, FALSE) -> 명V20 | J40: VARCHAR | K40: 20 | L40: - | M40: 20자리 이내 문자 | N40: Y | U40: N | V40: N
A41: N | B41: 생물종 | C41: bksp | D41: TBL_BIOSPC_RGN_LANG | E41: RGN_SE_CD | F41: 지역_구분_코드 | G41: 지역_구분_코드 | H41: 생물종_지역_언어 | I41: =VLOOKUP(E41,표준용어사전!$C$2:$D$494, 2, FALSE) -> 코드V50 | J41: VARCHAR | K41: 50 | L41: - | M41: 50자리 이내 문자 | N41: N | U41: N | V41: N
A42: N | B42: 생물종 | C42: bksp | D42: TBL_BIOSPC_RGN_LANG | E42: PRRTY_YN | F42: 우선_여부 | G42: 우선_여부 | H42: 생물종_지역_언어 | I42: =VLOOKUP(E42,표준용어사전!$C$2:$D$494, 2, FALSE) -> 여부C1 | J42: CHAR | K42: 1 | L42: - | M42: 1자리 문자 | N42: N | U42: N | V42: N
A43: N | B43: 생물종 | C43: bksp | D43: TBL_BIOSPC_RGN_LANG | E43: RGN_LANG_NM | F43: 지역_언어_명 | G43: 지역_언어_명 | H43: 생물종_지역_언어 | I43: =VLOOKUP(E43,표준용어사전!$C$2:$D$494, 2, FALSE) -> 명V256 | J43: VARCHAR | K43: 256 | L43: - | M43: 256자리 이내 문자 | N43: N | U43: N | V43: N
A44: N | B44: 생물종 | C44: bksp | D44: TBL_BIOSPC_RGN_LANG | E44: REG_DT | F44: 등록_일시 | G44: 등록_일시 | H44: 생물종_지역_언어 | I44: =VLOOKUP(E44,표준용어사전!$C$2:$D$494, 2, FALSE) -> 연월일시분초TS | J44: TIMESTAMP | K44: - | L44: - | M44: YYYYMMDDHH24MISS | N44: Y | U44: N | V44: N
A45: N | B45: 생물종 | C45: bksp | D45: TBL_BIOSPC_RGN_LANG | E45: REG_ID | F45: 등록_아이디 | G45: 등록_아이디 | H45: 생물종_지역_언어 | I45: =VLOOKUP(E45,표준용어사전!$C$2:$D$494, 2, FALSE) -> 명V20 | J45: VARCHAR | K45: 20 | L45: - | M45: 20자리 이내 문자 | N45: N | U45: N | V45: N
A46: N | B46: 생물종 | C46: bksp | D46: TBL_BIOSPC_RGN_LANG | E46: MDFCN_DT | F46: 수정_일시 | G46: 수정_일시 | H46: 생물종_지역_언어 | I46: =VLOOKUP(E46,표준용어사전!$C$2:$D$494, 2, FALSE) -> 연월일시분초TS | J46: TIMESTAMP | K46: - | L46: - | M46: YYYYMMDDHH24MISS | N46: N | U46: N | V46: N
A47: N | B47: 생물종 | C47: bksp | D47: TBL_BIOSPC_RGN_LANG | E47: MDFCN_ID | F47: 수정_아이디 | G47: 수정_아이디 | H47: 생물종_지역_언어 | I47: =VLOOKUP(E47,표준용어사전!$C$2:$D$494, 2, FALSE) -> 명V20 | J47: VARCHAR | K47: 20 | L47: - | M47: 20자리 이내 문자 | N47: N | U47: N | V47: N
A48: N | B48: 생물종 | C48: bksp | D48: TBL_BIOSPC_SNTFNM | E48: SNTFNM_NO | F48: 학명_번호 | G48: 학명_번호 | H48: 생물종_학명 | I48: =VLOOKUP(E48,표준용어사전!$C$2:$D$494, 2, FALSE) -> 번호I | J48: INT4 | K48: - | L48: - | M48: 0 이상의 정수 | N48: Y | O48: PK01 | U48: N | V48: N
A49: N | B49: 생물종 | C49: bksp | D49: TBL_BIOSPC_SNTFNM | E49: EOL_ID | F49: EOL_아이디 | G49: EOL_아이디 | H49: 생물종_학명 | I49: =VLOOKUP(E49,표준용어사전!$C$2:$D$494, 2, FALSE) -> 명V20 | J49: VARCHAR | K49: 20 | L49: - | M49: 20자리 이내 문자 | N49: Y | U49: N | V49: N
A50: N | B50: 생물종 | C50: bksp | D50: TBL_BIOSPC_SNTFNM | E50: CLCT_INST_SE_CD | F50: 수집_기관_구분_코드 | G50: 수집_기관_구분_코드 | H50: 생물종_학명 | I50: =VLOOKUP(E50,표준용어사전!$C$2:$D$494, 2, FALSE) -> 코드V50 | J50: VARCHAR | K50: 50 | L50: - | M50: 50자리 이내 문자 | N50: N | U50: N | V50: N
A51: N | B51: 생물종 | C51: bksp | D51: TBL_BIOSPC_SNTFNM | E51: SPCS_TXNM_SNTFNM | F51: 종_분류학_학명 | G51: 종_분류학_학명 | H51: 생물종_학명 | I51: =VLOOKUP(E51,표준용어사전!$C$2:$D$494, 2, FALSE) -> 학명V256 | J51: VARCHAR | K51: 256 | L51: - | M51: 256자리 이내 문자 | N51: N | U51: N | V51: N
A52: N | B52: 생물종 | C52: bksp | D52: TBL_BIOSPC_SNTFNM | E52: REG_DT | F52: 등록_일시 | G52: 등록_일시 | H52: 생물종_학명 | I52: =VLOOKUP(E52,표준용어사전!$C$2:$D$494, 2, FALSE) -> 연월일시분초TS | J52: TIMESTAMP | K52: - | L52: - | M52: YYYYMMDDHH24MISS | N52: Y | U52: N | V52: N
A53: N | B53: 생물종 | C53: bksp | D53: TBL_BIOSPC_SNTFNM | E53: REG_ID | F53: 등록_아이디 | G53: 등록_아이디 | H53: 생물종_학명 | I53: =VLOOKUP(E53,표준용어사전!$C$2:$D$494, 2, FALSE) -> 명V20 | J53: VARCHAR | K53: 20 | L53: - | M53: 20자리 이내 문자 | N53: N | U53: N | V53: N
A54: N | B54: 생물종 | C54: bksp | D54: TBL_BIOSPC_SNTFNM | E54: MDFCN_DT | F54: 수정_일시 | G54: 수정_일시 | H54: 생물종_학명 | I54: =VLOOKUP(E54,표준용어사전!$C$2:$D$494, 2, FALSE) -> 연월일시분초TS | J54: TIMESTAMP | K54: - | L54: - | M54: YYYYMMDDHH24MISS | N54: N | U54: N | V54: N
A55: N | B55: 생물종 | C55: bksp | D55: TBL_BIOSPC_SNTFNM | E55: MDFCN_ID | F55: 수정_아이디 | G55: 수정_아이디 | H55: 생물종_학명 | I55: =VLOOKUP(E55,표준용어사전!$C$2:$D$494, 2, FALSE) -> 명V20 | J55: VARCHAR | K55: 20 | L55: - | M55: 20자리 이내 문자 | N55: N | U55: N | V55: N
A56: N | B56: 생물종 | C56: bksp | D56: TBL_BIOSPC_SYNM | E56: SYNM_NO | F56: 동의어_번호 | G56: 동의어_번호 | H56: 생물종_동의어 | I56: =VLOOKUP(E56,표준용어사전!$C$2:$D$494, 2, FALSE) -> 번호I | J56: INT4 | K56: - | L56: - | M56: 0 이상의 정수 | N56: Y | O56: PK01 | U56: N | V56: N
A57: N | B57: 생물종 | C57: bksp | D57: TBL_BIOSPC_SYNM | E57: EOL_ID | F57: EOL_아이디 | G57: EOL_아이디 | H57: 생물종_동의어 | I57: =VLOOKUP(E57,표준용어사전!$C$2:$D$494, 2, FALSE) -> 명V20 | J57: VARCHAR | K57: 20 | L57: - | M57: 20자리 이내 문자 | N57: Y | U57: N | V57: N
...

Sheet 작성지침
A1: 항목 | B1: 설명 | C1: 구분
A2: 테이블 영문명 | B2: ○ 해당 컬럼이 소속된 테이블의 이름(영문명) | C2: 표준
A3: 컬럼 영문명 | B3: ○ 컬럼의 물리적 영문 이름으로 ‘표준용어정의서’에 등록된 용어를 사용 | C3: 표준
A4: 컬럼 한글명 | B4: ○ 해당 컬럼과 연관되는 속성의 이름과 동일하게 부여하며, 표준용어를 준수하여 부여할 컬럼 한글 명칭 | C4: 표준
A5: 컬럼 설명 | B5: ○ 컬럼에 대한 이해를 돕기 위하여 필요한 부가적인 설명 및 예외 사항 등을 기입 | C5: 표준
A6: 연관 엔터티명 | B6: ○ 해당 컬럼이 표현하는 논리적 데이터요소인 ‘엔터티명’을 기술 ○ ‘엔터티정의서’에 기록한 ‘엔터티명’으로 기술 | C6: 표준
A7: 연관 속성명 | B7: ○ 해당 컬럼이 표현하는 논리적 데이터요소인 ‘속성명’을 기술 ○ ‘속성정의서’에 기록한 ‘속성명’으로 기술 | C7: 표준
A8: 데이터 타입 | B8: ○ 컬럼 값의 물리적 표현 방식으로 DBMS 종속적인 데이터타입의 이름을 그대로 기록 | C8: 표준
A9: 데이터 길이 | B9: ○ ‘도메인정의서’의 ‘길이’를 기술 - ‘도메인정의서’에 없는 경우, 해당 컬럼의 값을 표현하기 위한 데이터의 길이로, DDL문에서 지정될 데이터 길이를 DBMS 종속적인 표현으로 기술 (DATE 타입과 같이 길이가 필요 없는 경우 생략) | C9: 표준
A10: 데이터소수점길이 | B10: ○ ‘도메인정의서’의 ‘데이터소수점길이’를 기술 - ‘도메인정의서’에 없는 경우, 해당 컬럼의 값을 표현하기 위한 데이터의 길이로, DDL문에서 지정될 데이터 길이를 DBMS 종속적인 표현으로 기술 (DATE 타입과 같이 길이가 필요 없는 경우 생략) | C10: 표준
A11: 데이터 형식 | B11: ○ 컬럼 값의 데이터 형식(혹은 샘플값) 기술 (예: 컬럼 값의 데이터 형식이 날짜인 경우, ‘yyyy-mm -dd’ 등 실제 데이터베이스에 저장되는 형식 기술) | C11: 표준
A12: Not Null 여부 | B12: ○ 데이터가 생성(Insert)되는 시점에 컬럼 값이 반드시 존재해야 하는지를 표시 - 값의 표시 : "Y" - Nullable, "N" - Not Null | C12: 표준
... A22: 공개/비공개 여부 | B22: ○ 해당 컬럼의 메타데이터 및 원천데이터 정보에 대한 공개 또는 비공개 여부(비공개의 경우 비공개 사유 기술) | C22: 표준

Sheet 표준용어사전
A1: No | B1: 용어명 | C1: 칼럼명 | D1: 도메인
A2: 1 | B2: 방문자_수_현황_연월 | C2: VSTR_CNT_PRST_YM | D2: 연월C6
A3: 2 | B3: 방문자_로그아웃_수 | C3: VSTR_LGT_CNT | D3: 수N10
A4: 3 | B4: 방문자_로그인_수 | C4: VSTR_LGN_CNT | D4: 수N10
A5: 4 | B5: 방문자_전문가_수 | C5: VSTR_EXPRT_CNT | D5: 수N10
A6: 5 | B6: 방문자_로그아웃_체류_시간 | C6: VSTR_LGT_STAY_HR | D6: 시분초N10
A7: 6 | B7: 방문자_로그인_체류_시간 | C7: VSTR_LGN_STAY_HR | D7: 시분초N10
A8: 7 | B8: 방문자_전문가_체류_시간 | C8: VSTR_EXPRT_STAY_HR | D8: 시분초N10
A9: 8 | B9: 콘텐츠_번호 | C9: CONTS_NO | D9: 번호N10
A10: 9 | B10: 기술_코드 | C10: TECH_CD | D10: 코드V50
A11: 10 | B11: 등록_일시 | C11: REG_DT | D11: 연월일시분초TS
A12: 11 | B12: 등록_아이디 | C12: REG_ID | D12: 명V20
A13: 12 | B13: 수정_일시 | C13: MDFCN_DT | D13: 연월일시분초TS
... A464: 463 | B464: KCI_논문_아이디 | C464: KCI_THSS_ID | D464: 명V50
